{
 "cells": [
  {
   "cell_type": "code",
   "execution_count": 4,
   "metadata": {},
   "outputs": [],
   "source": [
    "DMC_Model=DMC()"
   ]
  },
  {
   "cell_type": "code",
   "execution_count": 6,
   "metadata": {},
   "outputs": [],
   "source": [
    "from sklearn.utils import check_random_state\n",
    "from sklearn.base import BaseEstimator, ClassifierMixin\n",
    "\n",
    "from sklearn.utils._param_validation import Interval, StrOptions\n",
    "import numbers\n",
    "\n",
    "# param validation of an estimator\n",
    "class SomeEstimator(BaseEstimator,ClassifierMixin):\n",
    "    _parameter_constraints: dict = {\n",
    "        \"T\": [Interval(numbers.Integral, 1, None, closed=\"left\")],\n",
    "        \"discretization\": [StrOptions({\"kmeans\", \"Decision_tree\"})],\n",
    "        \"tol\": [Interval(numbers.Real, 0, None, closed=\"left\")],\n",
    "        \"X\": [\"array-like\",None],\n",
    "        \"random_state\":[\"random_state\"]}\n",
    "        \n",
    "    def __init__(self,\n",
    "                 X=None,\n",
    "                 n_clusters=10,\n",
    "                 discretization=\"kmeans\",\n",
    "                 tol=3.14,\n",
    "                 random_state=None):\n",
    "        self.n_clusters=n_clusters\n",
    "        self.discretization=discretization\n",
    "        self.tol=tol\n",
    "        self.X=X\n",
    "        self.random_state=random_state\n",
    "        self._validate_params()\n",
    "\n",
    "\n",
    "\n",
    "    def fit(X, y):\n",
    "        self._validate_params()"
   ]
  },
  {
   "cell_type": "code",
   "execution_count": 9,
   "metadata": {},
   "outputs": [
    {
     "ename": "NameError",
     "evalue": "name 'SomeEstimator' is not defined",
     "output_type": "error",
     "traceback": [
      "\u001b[1;31m---------------------------------------------------------------------------\u001b[0m",
      "\u001b[1;31mNameError\u001b[0m                                 Traceback (most recent call last)",
      "\u001b[1;32m~\\AppData\\Local\\Temp/ipykernel_20440/3313117109.py\u001b[0m in \u001b[0;36m<module>\u001b[1;34m\u001b[0m\n\u001b[1;32m----> 1\u001b[1;33m \u001b[0mprueba\u001b[0m\u001b[1;33m=\u001b[0m\u001b[0mSomeEstimator\u001b[0m\u001b[1;33m(\u001b[0m\u001b[0mN\u001b[0m\u001b[1;33m=\u001b[0m\u001b[1;34m\"DTaaa\"\u001b[0m\u001b[1;33m)\u001b[0m\u001b[1;33m\u001b[0m\u001b[1;33m\u001b[0m\u001b[0m\n\u001b[0m",
      "\u001b[1;31mNameError\u001b[0m: name 'SomeEstimator' is not defined"
     ]
    }
   ],
   "source": [
    "prueba=SomeEstimator(N=\"DTaaa\")"
   ]
  },
  {
   "cell_type": "code",
   "execution_count": 42,
   "metadata": {},
   "outputs": [],
   "source": []
  },
  {
   "cell_type": "code",
   "execution_count": 1,
   "metadata": {},
   "outputs": [
    {
     "name": "stderr",
     "output_type": "stream",
     "text": [
      "C:\\Users\\salva\\AppData\\Roaming\\Python\\Python39\\site-packages\\matplotlib\\projections\\__init__.py:63: UserWarning: Unable to import Axes3D. This may be due to multiple versions of Matplotlib being installed (e.g. as a system package and as a pip package). As a result, the 3D projection is not available.\n",
      "  warnings.warn(\"Unable to import Axes3D. This may be due to multiple versions of \"\n"
     ]
    }
   ],
   "source": [
    "import numpy as np\n",
    "import numpy as np\n",
    "import pandas as pd\n",
    "import matplotlib.pyplot as plt\n",
    "from tqdm import tqdm\n",
    "from sklearn.cluster import KMeans\n",
    "from sklearn.base import BaseEstimator, ClassifierMixin\n",
    "from sklearn.utils.validation import check_X_y, check_array, check_is_fitted\n",
    "from sklearn.utils import check_random_state\n",
    "from sklearn.utils._param_validation import Interval, StrOptions\n",
    "import numbers\n",
    "from itertools import combinations\n",
    "from DMC_class import DMC"
   ]
  },
  {
   "cell_type": "code",
   "execution_count": 1,
   "metadata": {},
   "outputs": [
    {
     "name": "stderr",
     "output_type": "stream",
     "text": [
      "C:\\Users\\salva\\AppData\\Roaming\\Python\\Python39\\site-packages\\matplotlib\\projections\\__init__.py:63: UserWarning: Unable to import Axes3D. This may be due to multiple versions of Matplotlib being installed (e.g. as a system package and as a pip package). As a result, the 3D projection is not available.\n",
      "  warnings.warn(\"Unable to import Axes3D. This may be due to multiple versions of \"\n"
     ]
    }
   ],
   "source": [
    "import importlib\n",
    "import DMC_class\n",
    "\n",
    "importlib.reload(DMC_class)\n",
    "from DMC_class import DMC"
   ]
  },
  {
   "cell_type": "code",
   "execution_count": 2,
   "metadata": {},
   "outputs": [],
   "source": [
    "prueba=DMC(N=-10)"
   ]
  },
  {
   "cell_type": "code",
   "execution_count": null,
   "metadata": {},
   "outputs": [],
   "source": []
  }
 ],
 "metadata": {
  "kernelspec": {
   "display_name": "base",
   "language": "python",
   "name": "python3"
  },
  "language_info": {
   "codemirror_mode": {
    "name": "ipython",
    "version": 3
   },
   "file_extension": ".py",
   "mimetype": "text/x-python",
   "name": "python",
   "nbconvert_exporter": "python",
   "pygments_lexer": "ipython3",
   "version": "3.9.7"
  }
 },
 "nbformat": 4,
 "nbformat_minor": 2
}
